Workbook

Sheet README
A1: 30-Year Naturally Dried Red Cedar – Complete Laboratory Procedural Record
A3: Dataset scope | B3: 49 aged-red-cedar specimens, MB IDs 000024–000072, recovered from 99 submitted screenshots in this ZIP.
A4: Primary source | B4: Detailed analyzer screens are primary; paired summary cards and analyzer screens are embedded.
A5: Procedural preservation | B5: Signal, source, recording duration, visualized interval, peak amplitude, geometry, damping, Q, fit, modulus, and radiation fields are retained.
A6: Spectral evidence | B6: Recorded-signal, amplitude-spectrum, and impulse-response plots are preserved visually.
A7: Raw-data limitation | B7: No raw audio, waveform arrays, FFT bins, or numerical impulse-response arrays were supplied.
A8: Duplicate capture | B8: The submitted ZIP contains one duplicate summary image for sample 000050; one summary card is paired with its detailed analyzer screen.
A9: Transcription policy | B9: Unreadable fields remain blank and are identified in Review Notes. Calculated verification fields remain separate from displayed source values.

Sheet Specimen Master
A1: Primary Measurements and Laboratory Metadata
A3: Sample ID | B3: Analyzer Sample Name | C3: Material / Aging | D3: Sample Length (mm) | E3: Sample Width (mm) | F3: Sample Thickness (mm) | G3: Sample Mass (g) | H3: Displayed Density (kg/m³) | I3: Calculated Density (kg/m³) | J3: Sample Nodal Lines (mm) | K3: Resonance Frequency (Hz) | L3: Time Constant (ms) | M3: Log Decrement | N3: Q Factor / Sustain | O3: Fitting (%) | P3: Displayed Young's Modulus (GPa) | Q3: Displayed Radiation Coefficient | R3: Calculated Radiation Coefficient | S3: Total Recording Length (s) | T3: Visualized Length (s) | U3: Peak Amplitude (dBFS) | V3: Signal Channel | W3: Selected Source | X3: Recorded Signal Plot | Y3: Amplitude Spectrum Plot | Z3: Impulse Response Plot | AA3: Summary Screenshot | AB3: Detailed Screenshot | AC3: Review Notes | AD3: Raw Audio Included | AE3: Numeric Waveform Included | AF3: Numeric FFT Bins Included | AG3: Numeric Impulse Response Included | AH3: Environmental Conditions Visible | AI3: Calibration Record Visible
A4: 000024 | B4: CA-00002 | C4: 30-Year Naturally Dried Red Cedar | D4: 533 | E4: 210 | F4: 4.1 | G4: 142 | H4: 309.4 | I4: =IFERROR(G4*1000000/(D4*E4*F4),"") | J4: 288 | K4: 60.9 | L4: 1160.8 | M4: 0.0141 | N4: 222 | O4: 92.5 | P4: 5.2 | Q4: 13.2 | R4: =IFERROR(SQRT(P4*1000000000/H4)/H4,"") | S4: 42.4 | T4: 6.3 | U4: -3.1 | V4: Signal 1 | W4: Mono | X4: Present | Y4: Present | Z4: Present | AA4: Screenshot 2026-08-02 011628.png | AB4: Screenshot 2026-08-02 011637.png | AD4: No | AE4: No – screenshot only | AF4: No – screenshot only | AG4: No – screenshot only | AH4: No | AI4: No
A5: 000025 | B5: CA3-0003 | C5: 30-Year Naturally Dried Red Cedar | D5: 533 | E5: 210 | F5: 4.2 | G5: 131 | H5: 278.7 | I5: =IFERROR(G5*1000000/(D5*E5*F5),"") | J5: 288 | K5: 60.7 | L5: 1177.7 | M5: 0.014 | N5: 224.7 | O5: 91.4 | P5: 4.4 | Q5: 14.3 | R5: =IFERROR(SQRT(P5*1000000000/H5)/H5,"") | S5: 33.2 | T5: 5.2 | U5: -3.4 | V5: Signal 1 | W5: Mono | X5: Present | Y5: Present | Z5: Present | AA5: Screenshot 2026-08-02 012531.png | AB5: Screenshot 2026-08-02 012618.png | AD5: No | AE5: No – screenshot only | AF5: No – screenshot only | AG5: No – screenshot only | AH5: No | AI5: No
A6: 000026 | B6: CA3-0004 | C6: 30-Year Naturally Dried Red Cedar | D6: 556 | E6: 206 | F6: 4 | G6: 145 | H6: 316.5 | I6: =IFERROR(G6*1000000/(D6*E6*F6),"") | J6: 300 | K6: 54.3 | L6: 1260.4 | M6: 0.0146 | N6: 214.9 | O6: 93.6 | P6: 5.2 | Q6: 12.9 | R6: =IFERROR(SQRT(P6*1000000000/H6)/H6,"") | S6: 37.1 | T6: 5.3 | U6: -4 | V6: Signal 1 | W6: Mono | X6: Present | Y6: Present | Z6: Present | AA6: Screenshot 2026-08-02 012649.png | AB6: Screenshot 2026-08-02 012712.png | AD6: No | AE6: No – screenshot only | AF6: No – screenshot only | AG6: No – screenshot only | AH6: No | AI6: No
A7: 000027 | B7: CA3-0005 | C7: 30-Year Naturally Dried Red Cedar | D7: 560 | E7: 205 | F7: 4.1 | G7: 144 | H7: 305.9 | I7: =IFERROR(G7*1000000/(D7*E7*F7),"") | J7: 302 | K7: 55.5 | L7: 1275.5 | M7: 0.0141 | N7: 222.2 | O7: 92.5 | P7: 5.2 | Q7: 13.5 | R7: =IFERROR(SQRT(P7*1000000000/H7)/H7,"") | S7: 44.4 | T7: 6.3 | U7: -6.8 | V7: Signal 1 | W7: Mono | X7: Present | Y7: Present | Z7: Present | AA7: Screenshot 2026-08-02 013342.png | AB7: Screenshot 2026-08-02 013410.png | AD7: No | AE7: No – screenshot only | AF7: No – screenshot only | AG7: No – screenshot only | AH7: No | AI7: No
A8: 000028 | B8: CA23-0006 | C8: 30-Year Naturally Dried Red Cedar | D8: 566 | E8: 200 | F8: 3.9 | G8: 129 | H8: 292.2 | I8: =IFERROR(G8*1000000/(D8*E8*F8),"") | J8: 306 | K8: 52.3 | L8: 1286.8 | M8: 0.0149 | N8: 211.3 | O8: 92.8 | P8: 5.1 | Q8: 14.3 | R8: =IFERROR(SQRT(P8*1000000000/H8)/H8,"") | S8: 26.6 | T8: 4.5 | U8: -6.1 | V8: Signal 1 | W8: Mono | X8: Present | Y8: Present | Z8: Present | AA8: Screenshot 2026-08-02 013418.png | AB8: Screenshot 2026-08-02 013428.png | AD8: No | AE8: No – screenshot only | AF8: No – screenshot only | AG8: No – screenshot only | AH8: No | AI8: No
A9: 000029 | B9: CA23-0007 | C9: 30-Year Naturally Dried Red Cedar | D9: 567 | E9: 202 | F9: 4 | G9: 136 | H9: 296.9 | I9: =IFERROR(G9*1000000/(D9*E9*F9),"") | J9: 306 | K9: 53 | L9: 1420.3 | M9: 0.0133 | N9: 236.4 | O9: 94.7 | P9: 5.1 | Q9: 13.9 | R9: =IFERROR(SQRT(P9*1000000000/H9)/H9,"") | S9: 25.7 | T9: 6.5 | U9: -4.6 | V9: Signal 1 | W9: Mono | X9: Present | Y9: Present | Z9: Present | AA9: Screenshot 2026-08-02 013438.png | AB9: Screenshot 2026-08-02 013450.png | AD9: No | AE9: No – screenshot only | AF9: No – screenshot only | AG9: No – screenshot only | AH9: No | AI9: No
A10: 000030 | B10: CA23-0008 | C10: 30-Year Naturally Dried Red Cedar | D10: 562 | E10: 205 | F10: 4 | G10: 148 | H10: 321.2 | I10: =IFERROR(G10*1000000/(D10*E10*F10),"") | J10: 303 | K10: 55.7 | L10: 1076.4 | M10: 0.0167 | N10: 188.2 | O10: 94.4 | P10: 5.8 | Q10: 13.3 | R10: =IFERROR(SQRT(P10*1000000000/H10)/H10,"") | S10: 37.9 | T10: 8.9 | U10: -4 | V10: Signal 1 | W10: Mono | X10: Present | Y10: Present | Z10: Present | AA10: Screenshot 2026-08-02 013458.png | AB10: Screenshot 2026-08-02 013513.png | AD10: No | AE10: No – screenshot only | AF10: No – screenshot only | AG10: No – screenshot only | AH10: No | AI10: No
A11: 000031 | B11: CA23-0009 | C11: 30-Year Naturally Dried Red Cedar | D11: 561 | E11: 202 | F11: 3.9 | G11: 134 | H11: 303.2 | I11: =IFERROR(G11*1000000/(D11*E11*F11),"") | J11: 303 | K11: 56.8 | L11: 1120.3 | M11: 0.0157 | N11: 200 | O11: 92.1 | P11: 6 | Q11: 14.7 | R11: =IFERROR(SQRT(P11*1000000000/H11)/H11,"") | S11: 36.7 | T11: 6.6 | U11: -3.4 | V11: Signal 1 | W11: Mono | X11: Present | Y11: Present | Z11: Present | AA11: Screenshot 2026-08-02 013522.png | AB11: Screenshot 2026-08-02 013535.png | AD11: No | AE11: No – screenshot only | AF11: No – screenshot only | AG11: No – screenshot only | AH11: No | AI11: No
A12: 000032 | B12: CA23-0010 | C12: 30-Year Naturally Dried Red Cedar | D12: 568 | E12: 204 | F12: 3.9 | G12: 138 | H12: 305.4 | I12: =IFERROR(G12*1000000/(D12*E12*F12),"") | J12: 307 | K12: 51.4 | L12: 1126.7 | M12: 0.0173 | N12: 182 | O12: 91.1 | P12: 5.2 | Q12: 13.5 | R12: =IFERROR(SQRT(P12*1000000000/H12)/H12,"") | S12: 33.1 | T12: 6.8 | U12: -3.4 | V12: Signal 1 | W12: Mono | X12: Present | Y12: Present | Z12: Present | AA12: Screenshot 2026-08-02 014059.png | AB12: Screenshot 2026-08-02 014120.png | AD12: No | AE12: No – screenshot only | AF12: No – screenshot only | AG12: No – screenshot only | AH12: No | AI12: No
A13: 000033 | B13: CA2-0011 | C13: 30-Year Naturally Dried Red Cedar | D13: 528 | E13: 200 | F13: 4 | G13: 135 | H13: 319.6 | I13: =IFERROR(G13*1000000/(D13*E13*F13),"") | J13: 285 | K13: 66.1 | L13: 1167.3 | M13: 0.013 | N13: 242.6 | O13: 90.3 | P13: 6.4 | Q13: 14 | R13: =IFERROR(SQRT(P13*1000000000/H13)/H13,"") | S13: 28.8 | T13: 5.3 | U13: -5.7 | V13: Signal 1 | W13: Mono | X13: Present | Y13: Present | Z13: Present | AA13: Screenshot 2026-08-02 014129.png | AB13: Screenshot 2026-08-02 014141.png | AD13: No | AE13: No – screenshot only | AF13: No – screenshot only | AG13: No – screenshot only | AH13: No | AI13: No
A14: 000034 | B14: CA2-0012 | C14: 30-Year Naturally Dried Red Cedar | D14: 524 | E14: 205 | F14: 4 | G14: 124 | H14: 288.6 | I14: =IFERROR(G14*1000000/(D14*E14*F14),"") | J14: 283 | K14: 61.6 | L14: 854.1 | M14: 0.019 | N14: 165.2 | O14: 91.5 | P14: 4.9 | Q14: 14.2 | R14: =IFERROR(SQRT(P14*1000000000/H14)/H14,"") | S14: 27.9 | T14: 5.1 | U14: -5.5 | V14: Signal 1 | W14: Mono | X14: Present | Y14: Present | Z14: Present | AA14: Screenshot 2026-08-02 014151.png | AB14: Screenshot 2026-08-02 014205.png | AD14: No | AE14: No – screenshot only | AF14: No – screenshot only | AG14: No – screenshot only | AH14: No | AI14: No
A15: 000035 | B15: CA2-0013 | C15: 30-Year Naturally Dried Red Cedar | D15: 530 | E15: 206 | F15: 3.9 | G15: 136 | H15: 319.4 | I15: =IFERROR(G15*1000000/(D15*E15*F15),"") | J15: 286 | K15: 60.7 | L15: 1245.3 | M15: 0.0132 | N15: 237.5 | O15: 90 | P15: 5.8 | Q15: 13.3 | R15: =IFERROR(SQRT(P15*1000000000/H15)/H15,"") | S15: 31.1 | T15: 7.1 | U15: -4.3 | V15: Signal 1 | W15: Mono | X15: Present | Y15: Present | Z15: Present | AA15: Screenshot 2026-08-02 014325.png | AB15: Screenshot 2026-08-02 014413.png | AD15: No | AE15: No – screenshot only | AF15: No – screenshot only | AG15: No – screenshot only | AH15: No | AI15: No
... A20: 000040 | B20: CA1-0018 | C20: 30-Year Naturally Dried Red Cedar | D20: 557 | E20: 205 | F20: 4 | G20: 157 | H20: 343.7 | I20: =IFERROR(G20*1000000/(D20*E20*F20),"") | J20: 301 | K20: 64.2 | L20: 1183.7 | M20: 0.0132 | N20: 238.6 | O20: 93 | P20: 8 | Q20: 14 | R20: =IFERROR(SQRT(P20*1000000000/H20)/H20,"") | S20: 31.8 | T20: 6.5 | U20: -5.3 | V20: Signal 1 | W20: Mono | X20: Present | Y20: Present | Z20: Present | AA20: Screenshot 2026-08-02 015723.png | AB20: Screenshot 2026-08-02 015748.png | AD20: No | AE20: No – screenshot only | AF20: No – screenshot only | AG20: No – screenshot only | AH20: No | AI20: No
A21: 000041 | B21: CA1-0019 | C21: 30-Year Naturally Dried Red Cedar | D21: 558 | E21: 208 | F21: 3.8 | G21: 139 | H21: 315.2 | I21: =IFERROR(G21*1000000/(D21*E21*F21),"") | J21: 301 | K21: 64.1 | L21: 889.9 | M21: 0.0175 | N21: 179.3 | O21: 89.2 | P21: 8.2 | R21: =IFERROR(SQRT(P21*1000000000/H21)/H21,"") | S21: 36.6 | T21: 7.5 | U21: -3.3 | V21: Signal 1 | W21: Mono | X21: Present | Y21: Present | Z21: Present | AA21: Screenshot 2026-08-02 070929.png | AB21: Screenshot 2026-08-02 070954.png | AC21: Unreadable/not reliably transcribed: Displayed Radiation Coefficient | AD21: No | AE21: No – screenshot only | AF21: No – screenshot only | AG21: No – screenshot only | AH21: No | AI21: No
A22: 000042 | B22: CA1-0020 | C22: 30-Year Naturally Dried Red Cedar | D22: 563 | E22: 205 | F22: 4.1 | G22: 156 | H22: 329.7 | I22: =IFERROR(G22*1000000/(D22*E22*F22),"") | J22: 304 | K22: 63.4 | L22: 1089.1 | M22: 0.0145 | N22: 217 | O22: 96.3 | P22: 7.5 | R22: =IFERROR(SQRT(P22*1000000000/H22)/H22,"") | S22: 49.2 | T22: 6.7 | U22: -3.3 | V22: Signal 1 | W22: Mono | X22: Present | Y22: Present | Z22: Present | AA22: Screenshot 2026-08-02 071024.png | AB22: Screenshot 2026-08-02 071058.png | AC22: Unreadable/not reliably transcribed: Displayed Radiation Coefficient | AD22: No | AE22: No – screenshot only | AF22: No – screenshot only | AG22: No – screenshot only | AH22: No | AI22: No
A23: 000043 | B23: CAE-0021 | C23: 30-Year Naturally Dried Red Cedar | D23: 560 | E23: 206 | F23: 3.8 | G23: 136 | H23: 310.2 | I23: =IFERROR(G23*1000000/(D23*E23*F23),"") | J23: 302 | K23: 60.3 | L23: 1191.6 | M23: 0.0139 | N23: 225.8 | O23: 93.7 | P23: 7.2 | Q23: 15.6 | R23: =IFERROR(SQRT(P23*1000000000/H23)/H23,"") | S23: 51.4 | T23: 7.1 | U23: -3.2 | V23: Signal 1 | W23: Mono | X23: Present | Y23: Present | Z23: Present | AA23: Screenshot 2026-08-02 071248.png | AB23: Screenshot 2026-08-02 071310.png | AD23: No | AE23: No – screenshot only | AF23: No – screenshot only | AG23: No – screenshot only | AH23: No | AI23: No
A24: 000044 | B24: CAE-0022 | C24: 30-Year Naturally Dried Red Cedar | D24: 561 | E24: 206 | F24: 4 | G24: 137 | H24: 296.4 | I24: =IFERROR(G24*1000000/(D24*E24*F24),"") | J24: 303 | K24: 58.6 | L24: 1178.2 | M24: 0.0145 | N24: 217 | O24: 93.3 | P24: 5.9 | R24: =IFERROR(SQRT(P24*1000000000/H24)/H24,"") | S24: 43.7 | T24: 7 | U24: -3.3 | V24: Signal 1 | W24: Mono | X24: Present | Y24: Present | Z24: Present | AA24: Screenshot 2026-08-02 071454.png | AB24: Screenshot 2026-08-02 071524.png | AC24: Unreadable/not reliably transcribed: Displayed Radiation Coefficient | AD24: No | AE24: No – screenshot only | AF24: No – screenshot only | AG24: No – screenshot only | AH24: No | AI24: No
A25: 000045 | B25: CAE-0023 | C25: 30-Year Naturally Dried Red Cedar | D25: 561 | E25: 205 | F25: 4 | G25: 141 | H25: 306.5 | I25: =IFERROR(G25*1000000/(D25*E25*F25),"") | J25: 303 | K25: 60.4 | L25: 1228.5 | M25: 0.0135 | N25: 232.9 | O25: 91.3 | P25: 6.5 | Q25: 15 | R25: =IFERROR(SQRT(P25*1000000000/H25)/H25,"") | S25: 43.9 | T25: 9.75 | U25: -3.2 | V25: Signal 1 | W25: Mono | X25: Present | Y25: Present | Z25: Present | AA25: Screenshot 2026-08-02 114241.png | AB25: Screenshot 2026-08-02 114318.png | AD25: No | AE25: No – screenshot only | AF25: No – screenshot only | AG25: No – screenshot only | AH25: No | AI25: No
A26: 000046 | B26: CAE-0024 | C26: 30-Year Naturally Dried Red Cedar | D26: 563 | E26: 205 | F26: 4.1 | G26: 144 | H26: 304.3 | I26: =IFERROR(G26*1000000/(D26*E26*F26),"") | J26: 304 | K26: 62.6 | L26: 1214.9 | M26: 0.0132 | N26: 238.8 | O26: 93.3 | P26: 6.7 | Q26: 15.4 | R26: =IFERROR(SQRT(P26*1000000000/H26)/H26,"") | S26: 48.8 | T26: 6.1 | U26: -3.2 | V26: Signal 1 | W26: Mono | X26: Present | Y26: Present | Z26: Present | AA26: Screenshot 2026-08-02 114343.png | AB26: Screenshot 2026-08-02 114443.png | AD26: No | AE26: No – screenshot only | AF26: No – screenshot only | AG26: No – screenshot only | AH26: No | AI26: No
A27: 000047 | B27: CAE-0025 | C27: 30-Year Naturally Dried Red Cedar | D27: 564 | E27: 205 | F27: 4.2 | G27: 160 | H27: 329.5 | I27: =IFERROR(G27*1000000/(D27*E27*F27),"") | J27: 305 | K27: 60.2 | L27: 1146.3 | M27: 0.0145 | N27: 216.8 | O27: 94.6 | P27: 6.4 | Q27: 13.4 | R27: =IFERROR(SQRT(P27*1000000000/H27)/H27,"") | S27: 41.7 | T27: 5.3 | V27: Signal 1 | W27: Mono | X27: Present | Y27: Present | Z27: Present | AA27: Screenshot 2026-08-02 114500.png | AB27: Screenshot 2026-08-02 114531.png | AC27: Unreadable/not reliably transcribed: Peak Amplitude (dBFS) | AD27: No | AE27: No – screenshot only | AF27: No – screenshot only | AG27: No – screenshot only | AH27: No | AI27: No
A28: 000048 | B28: CA3-0026 | C28: 30-Year Naturally Dried Red Cedar | D28: 563 | E28: 218 | F28: 3.9 | G28: 148 | H28: 309.2 | I28: =IFERROR(G28*1000000/(D28*E28*F28),"") | J28: 304 | K28: 51.3 | L28: 1133.6 | M28: 0.0172 | N28: 182.7 | O28: 90 | P28: 5.1 | Q28: 13.1 | R28: =IFERROR(SQRT(P28*1000000000/H28)/H28,"") | S28: 45.7 | T28: 5.8 | U28: -3.7 | V28: Signal 1 | W28: Mono | X28: Present | Y28: Present | Z28: Present | AA28: Screenshot 2026-08-02 114555.png | AB28: Screenshot 2026-08-02 114622.png | AD28: No | AE28: No – screenshot only | AF28: No – screenshot only | AG28: No – screenshot only | AH28: No | AI28: No
A29: 000049 | B29: CA3-0027 | C29: 30-Year Naturally Dried Red Cedar | D29: 563 | E29: 218 | F29: 3.9 | G29: 156 | H29: 325.9 | I29: =IFERROR(G29*1000000/(D29*E29*F29),"") | J29: 304 | K29: 52.3 | L29: 1411.7 | M29: 0.0135 | N29: 232 | O29: 91.9 | P29: 5.5 | R29: =IFERROR(SQRT(P29*1000000000/H29)/H29,"") | S29: 38.2 | T29: 5 | U29: -3.3 | V29: Signal 1 | W29: Mono | X29: Present | Y29: Present | Z29: Present | AA29: Screenshot 2026-08-02 114640.png | AB29: Screenshot 2026-08-02 114709.png | AC29: Unreadable/not reliably transcribed: Displayed Radiation Coefficient | AD29: No | AE29: No – screenshot only | AF29: No – screenshot only | AG29: No – screenshot only | AH29: No | AI29: No
A30: 000050 | B30: CA3-0028 | C30: 30-Year Naturally Dried Red Cedar | D30: 563 | E30: 218 | F30: 4 | G30: 151 | H30: 307.6 | I30: =IFERROR(G30*1000000/(D30*E30*F30),"") | J30: 304 | K30: 53.8 | L30: 1384.2 | M30: 0.0134 | N30: 234 | O30: 93.7 | P30: 5.3 | Q30: 13.5 | R30: =IFERROR(SQRT(P30*1000000000/H30)/H30,"") | S30: 37 | T30: 6.7 | U30: -3.3 | V30: Signal 1 | W30: Mono | X30: Present | Y30: Present | Z30: Present | AA30: Screenshot 2026-08-02 114734.png | AB30: Screenshot 2026-08-02 114746.png | AD30: No | AE30: No – screenshot only | AF30: No – screenshot only | AG30: No – screenshot only | AH30: No | AI30: No
A31: 000051 | B31: CA3-0029 | C31: 30-Year Naturally Dried Red Cedar | D31: 561 | E31: 218 | F31: 3.9 | G31: 149 | H31: 312.4 | I31: =IFERROR(G31*1000000/(D31*E31*F31),"") | J31: 303 | K31: 53.2 | L31: 1438.2 | M31: 0.0131 | N31: 240.2 | O31: 96.9 | P31: 5.4 | R31: =IFERROR(SQRT(P31*1000000000/H31)/H31,"") | S31: 41.1 | T31: 7.6 | U31: -4.4 | V31: Signal 1 | W31: Mono | X31: Present | Y31: Present | Z31: Present | AA31: Screenshot 2026-08-02 114756.png | AB31: Screenshot 2026-08-02 114819.png | AC31: Unreadable/not reliably transcribed: Displayed Radiation Coefficient | AD31: No | AE31: No – screenshot only | AF31: No – screenshot only | AG31: No – screenshot only | AH31: No | AI31: No
A32: 000052 | B32: CA3-0030 | C32: 30-Year Naturally Dried Red Cedar | D32: 561 | E32: 218 | F32: 3.8 | G32: 147 | H32: 316.3 | I32: =IFERROR(G32*1000000/(D32*E32*F32),"") | J32: 303 | K32: 53.9 | L32: 1285.9 | M32: 0.0144 | N32: 217.8 | O32: 93.2 | P32: 5.9 | Q32: 13.7 | R32: =IFERROR(SQRT(P32*1000000000/H32)/H32,"") | S32: 25.8 | T32: 7.2 | U32: -3.3 | V32: Signal 1 | W32: Mono | X32: Present | Y32: Present | Z32: Present | AA32: Screenshot 2026-08-02 120029.png | AB32: Screenshot 2026-08-02 120041.png | AD32: No | AE32: No – screenshot only | AF32: No – screenshot only | AG32: No – screenshot only | AH32: No | AI32: No
A33: 000053 | B33: CA23-0031 | C33: 30-Year Naturally Dried Red Cedar | D33: 579 | E33: 218 | F33: 3.9 | G33: 149 | H33: 302.7 | I33: =IFERROR(G33*1000000/(D33*E33*F33),"") | J33: 313 | K33: 55.9 | L33: 1213.7 | M33: 0.0147 | N33: 213.3 | O33: 96.6 | P33: 6.6 | Q33: 15.4 | R33: =IFERROR(SQRT(P33*1000000000/H33)/H33,"") | S33: 40.2 | T33: 7.9 | U33: -3.5 | V33: Signal 1 | W33: Mono | X33: Present | Y33: Present | Z33: Present | AA33: Screenshot 2026-08-02 120113.png | AB33: Screenshot 2026-08-02 120219.png | AD33: No | AE33: No – screenshot only | AF33: No – screenshot only | AG33: No – screenshot only | AH33: No | AI33: No
A34: 000054 | B34: CA23-0032 | C34: 30-Year Naturally Dried Red Cedar | D34: 574 | E34: 219 | F34: 4 | G34: 168 | H34: 334.1 | I34: =IFERROR(G34*1000000/(D34*E34*F34),"") | J34: 310 | K34: 54.9 | L34: 1397.3 | M34: 0.013 | N34: 240.9 | O34: 96.4 | P34: 6.4 | Q34: 13.1 | R34: =IFERROR(SQRT(P34*1000000000/H34)/H34,"") | S34: 33.5 | T34: 5.7 | U34: -3.9 | V34: Signal 1 | W34: Mono | X34: Present | Y34: Present | Z34: Present | AA34: Screenshot 2026-08-02 120239.png | AB34: Screenshot 2026-08-02 120606.png | AD34: No | AE34: No – screenshot only | AF34: No – screenshot only | AG34: No – screenshot only | AH34: No | AI34: No
A35: 000055 | B35: CA23-0033 | C35: 30-Year Naturally Dried Red Cedar | D35: 578 | E35: 216 | F35: 4 | G35: 155 | H35: 310.4 | I35: =IFERROR(G35*1000000/(D35*E35*F35),"") | J35: 312 | K35: 51.8 | L35: 1318.3 | M35: 0.0146 | N35: 214.7 | O35: 95.2 | P35: 5.5 | R35: =IFERROR(SQRT(P35*1000000000/H35)/H35,"") | S35: 33 | T35: 6.1 | V35: Signal 1 | W35: Mono | X35: Present | Y35: Present | Z35: Present | AA35: Screenshot 2026-08-02 120654.png | AB35: Screenshot 2026-08-02 120728.png | AC35: Unreadable/not reliably transcribed: Displayed Radiation Coefficient, Peak Amplitude (dBFS) | AD35: No | AE35: No – screenshot only | AF35: No – screenshot only | AG35: No – screenshot only | AH35: No | AI35: No
A36: 000056 | B36: CA23-0034 | C36: 30-Year Naturally Dried Red Cedar | D36: 578 | E36: 217 | F36: 3.9 | H36: 325 | I36: =IFERROR(G36*1000000/(D36*E36*F36),"") | J36: 312 | K36: 53.4 | L36: 1390.8 | M36: 0.0135 | N36: 233.1 | O36: 96.1 | P36: 6.4 | R36: =IFERROR(SQRT(P36*1000000000/H36)/H36,"") | S36: 33.9 | T36: 6.1 | U36: -3.3 | V36: Signal 1 | W36: Mono | X36: Present | Y36: Present | Z36: Present | AA36: Screenshot 2026-08-02 120754.png | AB36: Screenshot 2026-08-02 120815.png | AC36: Unreadable/not reliably transcribed: Sample Mass (g), Displayed Radiation Coefficient | AD36: No | AE36: No – screenshot only | AF36: No – screenshot only | AG36: No – screenshot only | AH36: No | AI36: No
A37: 000057 | B37: CA23-0035 | C37: 30-Year Naturally Dried Red Cedar | D37: 579 | E37: 218 | F37: 3.9 | G37: 157 | H37: 318.9 | I37: =IFERROR(G37*1000000/(D37*E37*F37),"") | J37: 313 | K37: 52.6 | L37: 1375.9 | M37: 0.0138 | N37: 227.4 | O37: 93.5 | P37: 6 | R37: =IFERROR(SQRT(P37*1000000000/H37)/H37,"") | S37: 33.3 | T37: 7.7 | V37: Signal 1 | W37: Mono | X37: Present | Y37: Present | Z37: Present | AA37: Screenshot 2026-08-02 120834.png | AB37: Screenshot 2026-08-02 120847.png | AC37: Unreadable/not reliably transcribed: Displayed Radiation Coefficient, Peak Amplitude (dBFS) | AD37: No | AE37: No – screenshot only | AF37: No – screenshot only | AG37: No – screenshot only | AH37: No | AI37: No
A38: 000058 | B38: CA2-0036 | C38: 30-Year Naturally Dried Red Cedar | D38: 570 | E38: 219 | F38: 3.9 | G38: 141 | H38: 289.6 | I38: =IFERROR(G38*1000000/(D38*E38*F38),"") | J38: 308 | K38: 51.4 | L38: 1260.4 | M38: 0.0154 | N38: 203.5 | O38: 94.7 | P38: 5 | Q38: 14.3 | R38: =IFERROR(SQRT(P38*1000000000/H38)/H38,"") | S38: 33.2 | T38: 6.7 | U38: -3.2 | V38: Signal 1 | W38: Mono | X38: Present | Y38: Present | Z38: Present | AA38: Screenshot 2026-08-02 120914.png | AB38: Screenshot 2026-08-02 120944.png | AD38: No | AE38: No – screenshot only | AF38: No – screenshot only | AG38: No – screenshot only | AH38: No | AI38: No
A39: 000059 | B39: CA2-0037 | C39: 30-Year Naturally Dried Red Cedar | D39: 570 | E39: 218 | F39: 4.1 | G39: 147 | H39: 268.5 | I39: =IFERROR(G39*1000000/(D39*E39*F39),"") | J39: 308 | K39: 53.5 | L39: 1429.7 | M39: 0.0131 | N39: 240.4 | O39: 95.6 | P39: 4.9 | R39: =IFERROR(SQRT(P39*1000000000/H39)/H39,"") | S39: 38.1 | T39: 6.5 | U39: -3.3 | V39: Signal 1 | W39: Mono | X39: Present | Y39: Present | Z39: Present | AA39: Screenshot 2026-08-02 121158.png | AB39: Screenshot 2026-08-02 121225.png | AC39: Unreadable/not reliably transcribed: Displayed Radiation Coefficient | AD39: No | AE39: No – screenshot only | AF39: No – screenshot only | AG39: No – screenshot only | AH39: No | AI39: No
A40: 000060 | B40: CA2-0038 | C40: 30-Year Naturally Dried Red Cedar | D40: 570 | E40: 222 | F40: 3.9 | G40: 147 | H40: 297.9 | I40: =IFERROR(G40*1000000/(D40*E40*F40),"") | J40: 308 | K40: 57.5 | L40: 1218.3 | M40: 0.0143 | N40: 220 | O40: 93.9 | P40: 6.4 | Q40: 15.6 | R40: =IFERROR(SQRT(P40*1000000000/H40)/H40,"") | S40: 28.8 | T40: 5.8 | U40: -3.2 | V40: Signal 1 | W40: Mono | X40: Present | Y40: Present | Z40: Present | AA40: Screenshot 2026-08-02 121233.png | AB40: Screenshot 2026-08-02 121243.png | AD40: No | AE40: No – screenshot only | AF40: No – screenshot only | AG40: No – screenshot only | AH40: No | AI40: No
A41: 000061 | B41: CA2-0039 | C41: 30-Year Naturally Dried Red Cedar | D41: 570 | E41: 219 | F41: 4 | G41: 149 | H41: 298.4 | I41: =IFERROR(G41*1000000/(D41*E41*F41),"") | J41: 308 | K41: 52.5 | L41: 1259.2 | M41: 0.0151 | N41: 207.7 | O41: 96.8 | P41: 5.1 | Q41: 13.9 | R41: =IFERROR(SQRT(P41*1000000000/H41)/H41,"") | S41: 28.9 | T41: 6.5 | U41: -3.2 | V41: Signal 1 | W41: Mono | X41: Present | Y41: Present | Z41: Present | AA41: Screenshot 2026-08-02 121250.png | AB41: Screenshot 2026-08-02 121304.png | AD41: No | AE41: No – screenshot only | AF41: No – screenshot only | AG41: No – screenshot only | AH41: No | AI41: No
A42: 000062 | B42: CA2-0040 | C42: 30-Year Naturally Dried Red Cedar | D42: 570 | E42: 218 | F42: 3.9 | G42: 147 | H42: 303.3 | I42: =IFERROR(G42*1000000/(D42*E42*F42),"") | J42: 308 | K42: 50.8 | L42: 1252.7 | M42: 0.0157 | N42: 199.9 | O42: 95.5 | P42: 5.1 | Q42: 13.5 | R42: =IFERROR(SQRT(P42*1000000000/H42)/H42,"") | S42: 27.8 | T42: 5.8 | U42: -3.2 | V42: Signal 1 | W42: Mono | X42: Present | Y42: Present | Z42: Present | AA42: Screenshot 2026-08-02 121311.png | AB42: Screenshot 2026-08-02 121324.png | AD42: No | AE42: No – screenshot only | AF42: No – screenshot only | AG42: No – screenshot only | AH42: No | AI42: No
A43: 000063 | B43: CA1-0041 | C43: 30-Year Naturally Dried Red Cedar | D43: 585 | E43: 210 | F43: 4 | G43: 175 | H43: 356.1 | I43: =IFERROR(G43*1000000/(D43*E43*F43),"") | J43: 316 | K43: 57.4 | L43: 1230 | M43: 0.0139 | N43: 225.3 | O43: 96.3 | P43: 8 | Q43: 13.4 | R43: =IFERROR(SQRT(P43*1000000000/H43)/H43,"") | S43: 19.4 | T43: 5.2 | U43: -5.6 | V43: Signal 1 | W43: Mono | X43: Present | Y43: Present | Z43: Present | AA43: Screenshot 2026-08-02 121333.png | AB43: Screenshot 2026-08-02 121357.png | AD43: No | AE43: No – screenshot only | AF43: No – screenshot only | AG43: No – screenshot only | AH43: No | AI43: No
A44: 000064 | B44: CA1-0042 | C44: 30-Year Naturally Dried Red Cedar | D44: 585 | E44: 210 | F44: 4 | G44: 171 | H44: 348 | I44: =IFERROR(G44*1000000/(D44*E44*F44),"") | J44: 316 | K44: 57.1 | L44: 1228.8 | M44: 0.0143 | N44: 220.3 | O44: 96.5 | P44: 7.8 | Q44: 13.6 | R44: =IFERROR(SQRT(P44*1000000000/H44)/H44,"") | S44: 20.2 | T44: 4.2 | U44: -3.2 | V44: Signal 1 | W44: Mono | X44: Present | Y44: Present | Z44: Present | AA44: Screenshot 2026-08-02 121511.png | AB44: Screenshot 2026-08-02 121537.png | AD44: No | AE44: No – screenshot only | AF44: No – screenshot only | AG44: No – screenshot only | AH44: No | AI44: No
A45: 000065 | B45: CA1-0043 | C45: 30-Year Naturally Dried Red Cedar | D45: 585 | E45: 210 | F45: 4 | G45: 170 | H45: 346 | I45: =IFERROR(G45*1000000/(D45*E45*F45),"") | J45: 316 | K45: 57.6 | L45: 1237.7 | M45: 0.014 | N45: 223.9 | O45: 90.7 | P45: 7.9 | R45: =IFERROR(SQRT(P45*1000000000/H45)/H45,"") | S45: 22.8 | T45: 5.5 | U45: -3.5 | V45: Signal 1 | W45: Mono | X45: Present | Y45: Present | Z45: Present | AA45: Screenshot 2026-08-02 121551.png | AB45: Screenshot 2026-08-02 121626.png | AC45: Unreadable/not reliably transcribed: Displayed Radiation Coefficient | AD45: No | AE45: No – screenshot only | AF45: No – screenshot only | AG45: No – screenshot only | AH45: No | AI45: No
...

Sheet Acquisition Procedure
A1: Acquisition, Signal Processing, and Procedural Metadata
A3: Sample ID | B3: Analyzer Sample Name | C3: Signal Channel | D3: Selected Source | E3: Recorded Signal Plot | F3: Amplitude Spectrum Plot | G3: Impulse Response Plot | H3: Total Recording Length (s) | I3: Visualized Length (s) | J3: Peak Amplitude (dBFS) | K3: Fitting (%) | L3: Time Constant (ms) | M3: Log Decrement | N3: Q Factor / Sustain | O3: Raw Audio Included | P3: Numeric Waveform Included | Q3: Numeric FFT Bins Included | R3: Numeric Impulse Response Included | S3: Environmental Conditions Visible | T3: Calibration Record Visible | U3: Summary Screenshot | V3: Detailed Screenshot | W3: Review Notes
A4: 000024 | B4: CA-00002 | C4: Signal 1 | D4: Mono | E4: Present | F4: Present | G4: Present | H4: 42.4 | I4: 6.3 | J4: -3.1 | K4: 92.5 | L4: 1160.8 | M4: 0.0141 | N4: 222 | O4: No | P4: No – screenshot only | Q4: No – screenshot only | R4: No – screenshot only | S4: No | T4: No | U4: Screenshot 2026-08-02 011628.png | V4: Screenshot 2026-08-02 011637.png
A5: 000025 | B5: CA3-0003 | C5: Signal 1 | D5: Mono | E5: Present | F5: Present | G5: Present | H5: 33.2 | I5: 5.2 | J5: -3.4 | K5: 91.4 | L5: 1177.7 | M5: 0.014 | N5: 224.7 | O5: No | P5: No – screenshot only | Q5: No – screenshot only | R5: No – screenshot only | S5: No | T5: No | U5: Screenshot 2026-08-02 012531.png | V5: Screenshot 2026-08-02 012618.png
A6: 000026 | B6: CA3-0004 | C6: Signal 1 | D6: Mono | E6: Present | F6: Present | G6: Present | H6: 37.1 | I6: 5.3 | J6: -4 | K6: 93.6 | L6: 1260.4 | M6: 0.0146 | N6: 214.9 | O6: No | P6: No – screenshot only | Q6: No – screenshot only | R6: No – screenshot only | S6: No | T6: No | U6: Screenshot 2026-08-02 012649.png | V6: Screenshot 2026-08-02 012712.png
A7: 000027 | B7: CA3-0005 | C7: Signal 1 | D7: Mono | E7: Present | F7: Present | G7: Present | H7: 44.4 | I7: 6.3 | J7: -6.8 | K7: 92.5 | L7: 1275.5 | M7: 0.0141 | N7: 222.2 | O7: No | P7: No – screenshot only | Q7: No – screenshot only | R7: No – screenshot only | S7: No | T7: No | U7: Screenshot 2026-08-02 013342.png | V7: Screenshot 2026-08-02 013410.png
A8: 000028 | B8: CA23-0006 | C8: Signal 1 | D8: Mono | E8: Present | F8: Present | G8: Present | H8: 26.6 | I8: 4.5 | J8: -6.1 | K8: 92.8 | L8: 1286.8 | M8: 0.0149 | N8: 211.3 | O8: No | P8: No – screenshot only | Q8: No – screenshot only | R8: No – screenshot only | S8: No | T8: No | U8: Screenshot 2026-08-02 013418.png | V8: Screenshot 2026-08-02 013428.png
A9: 000029 | B9: CA23-0007 | C9: Signal 1 | D9: Mono | E9: Present | F9: Present | G9: Present | H9: 25.7 | I9: 6.5 | J9: -4.6 | K9: 94.7 | L9: 1420.3 | M9: 0.0133 | N9: 236.4 | O9: No | P9: No – screenshot only | Q9: No – screenshot only | R9: No – screenshot only | S9: No | T9: No | U9: Screenshot 2026-08-02 013438.png | V9: Screenshot 2026-08-02 013450.png
A10: 000030 | B10: CA23-0008 | C10: Signal 1 | D10: Mono | E10: Present | F10: Present | G10: Present | H10: 37.9 | I10: 8.9 | J10: -4 | K10: 94.4 | L10: 1076.4 | M10: 0.0167 | N10: 188.2 | O10: No | P10: No – screenshot only | Q10: No – screenshot only | R10: No – screenshot only | S10: No | T10: No | U10: Screenshot 2026-08-02 013458.png | V10: Screenshot 2026-08-02 013513.png
A11: 000031 | B11: CA23-0009 | C11: Signal 1 | D11: Mono | E11: Present | F11: Present | G11: Present | H11: 36.7 | I11: 6.6 | J11: -3.4 | K11: 92.1 | L11: 1120.3 | M11: 0.0157 | N11: 200 | O11: No | P11: No – screenshot only | Q11: No – screenshot only | R11: No – screenshot only | S11: No | T11: No | U11: Screenshot 2026-08-02 013522.png | V11: Screenshot 2026-08-02 013535.png
A12: 000032 | B12: CA23-0010 | C12: Signal 1 | D12: Mono | E12: Present | F12: Present | G12: Present | H12: 33.1 | I12: 6.8 | J12: -3.4 | K12: 91.1 | L12: 1126.7 | M12: 0.0173 | N12: 182 | O12: No | P12: No – screenshot only | Q12: No – screenshot only | R12: No – screenshot only | S12: No | T12: No | U12: Screenshot 2026-08-02 014059.png | V12: Screenshot 2026-08-02 014120.png
A13: 000033 | B13: CA2-0011 | C13: Signal 1 | D13: Mono | E13: Present | F13: Present | G13: Present | H13: 28.8 | I13: 5.3 | J13: -5.7 | K13: 90.3 | L13: 1167.3 | M13: 0.013 | N13: 242.6 | O13: No | P13: No – screenshot only | Q13: No – screenshot only | R13: No – screenshot only | S13: No | T13: No | U13: Screenshot 2026-08-02 014129.png | V13: Screenshot 2026-08-02 014141.png
A14: 000034 | B14: CA2-0012 | C14: Signal 1 | D14: Mono | E14: Present | F14: Present | G14: Present | H14: 27.9 | I14: 5.1 | J14: -5.5 | K14: 91.5 | L14: 854.1 | M14: 0.019 | N14: 165.2 | O14: No | P14: No – screenshot only | Q14: No – screenshot only | R14: No – screenshot only | S14: No | T14: No | U14: Screenshot 2026-08-02 014151.png | V14: Screenshot 2026-08-02 014205.png
A15: 000035 | B15: CA2-0013 | C15: Signal 1 | D15: Mono | E15: Present | F15: Present | G15: Present | H15: 31.1 | I15: 7.1 | J15: -4.3 | K15: 90 | L15: 1245.3 | M15: 0.0132 | N15: 237.5 | O15: No | P15: No – screenshot only | Q15: No – screenshot only | R15: No – screenshot only | S15: No | T15: No | U15: Screenshot 2026-08-02 014325.png | V15: Screenshot 2026-08-02 014413.png
... A20: 000040 | B20: CA1-0018 | C20: Signal 1 | D20: Mono | E20: Present | F20: Present | G20: Present | H20: 31.8 | I20: 6.5 | J20: -5.3 | K20: 93 | L20: 1183.7 | M20: 0.0132 | N20: 238.6 | O20: No | P20: No – screenshot only | Q20: No – screenshot only | R20: No – screenshot only | S20: No | T20: No | U20: Screenshot 2026-08-02 015723.png | V20: Screenshot 2026-08-02 015748.png
A21: 000041 | B21: CA1-0019 | C21: Signal 1 | D21: Mono | E21: Present | F21: Present | G21: Present | H21: 36.6 | I21: 7.5 | J21: -3.3 | K21: 89.2 | L21: 889.9 | M21: 0.0175 | N21: 179.3 | O21: No | P21: No – screenshot only | Q21: No – screenshot only | R21: No – screenshot only | S21: No | T21: No | U21: Screenshot 2026-08-02 070929.png | V21: Screenshot 2026-08-02 070954.png | W21: Unreadable/not reliably transcribed: Displayed Radiation Coefficient
A22: 000042 | B22: CA1-0020 | C22: Signal 1 | D22: Mono | E22: Present | F22: Present | G22: Present | H22: 49.2 | I22: 6.7 | J22: -3.3 | K22: 96.3 | L22: 1089.1 | M22: 0.0145 | N22: 217 | O22: No | P22: No – screenshot only | Q22: No – screenshot only | R22: No – screenshot only | S22: No | T22: No | U22: Screenshot 2026-08-02 071024.png | V22: Screenshot 2026-08-02 071058.png | W22: Unreadable/not reliably transcribed: Displayed Radiation Coefficient
A23: 000043 | B23: CAE-0021 | C23: Signal 1 | D23: Mono | E23: Present | F23: Present | G23: Present | H23: 51.4 | I23: 7.1 | J23: -3.2 | K23: 93.7 | L23: 1191.6 | M23: 0.0139 | N23: 225.8 | O23: No | P23: No – screenshot only | Q23: No – screenshot only | R23: No – screenshot only | S23: No | T23: No | U23: Screenshot 2026-08-02 071248.png | V23: Screenshot 2026-08-02 071310.png
A24: 000044 | B24: CAE-0022 | C24: Signal 1 | D24: Mono | E24: Present | F24: Present | G24: Present | H24: 43.7 | I24: 7 | J24: -3.3 | K24: 93.3 | L24: 1178.2 | M24: 0.0145 | N24: 217 | O24: No | P24: No – screenshot only | Q24: No – screenshot only | R24: No – screenshot only | S24: No | T24: No | U24: Screenshot 2026-08-02 071454.png | V24: Screenshot 2026-08-02 071524.png | W24: Unreadable/not reliably transcribed: Displayed Radiation Coefficient
A25: 000045 | B25: CAE-0023 | C25: Signal 1 | D25: Mono | E25: Present | F25: Present | G25: Present | H25: 43.9 | I25: 9.75 | J25: -3.2 | K25: 91.3 | L25: 1228.5 | M25: 0.0135 | N25: 232.9 | O25: No | P25: No – screenshot only | Q25: No – screenshot only | R25: No – screenshot only | S25: No | T25: No | U25: Screenshot 2026-08-02 114241.png | V25: Screenshot 2026-08-02 114318.png
A26: 000046 | B26: CAE-0024 | C26: Signal 1 | D26: Mono | E26: Present | F26: Present | G26: Present | H26: 48.8 | I26: 6.1 | J26: -3.2 | K26: 93.3 | L26: 1214.9 | M26: 0.0132 | N26: 238.8 | O26: No | P26: No – screenshot only | Q26: No – screenshot only | R26: No – screenshot only | S26: No | T26: No | U26: Screenshot 2026-08-02 114343.png | V26: Screenshot 2026-08-02 114443.png
A27: 000047 | B27: CAE-0025 | C27: Signal 1 | D27: Mono | E27: Present | F27: Present | G27: Present | H27: 41.7 | I27: 5.3 | K27: 94.6 | L27: 1146.3 | M27: 0.0145 | N27: 216.8 | O27: No | P27: No – screenshot only | Q27: No – screenshot only | R27: No – screenshot only | S27: No | T27: No | U27: Screenshot 2026-08-02 114500.png | V27: Screenshot 2026-08-02 114531.png | W27: Unreadable/not reliably transcribed: Peak Amplitude (dBFS)
A28: 000048 | B28: CA3-0026 | C28: Signal 1 | D28: Mono | E28: Present | F28: Present | G28: Present | H28: 45.7 | I28: 5.8 | J28: -3.7 | K28: 90 | L28: 1133.6 | M28: 0.0172 | N28: 182.7 | O28: No | P28: No – screenshot only | Q28: No – screenshot only | R28: No – screenshot only | S28: No | T28: No | U28: Screenshot 2026-08-02 114555.png | V28: Screenshot 2026-08-02 114622.png
A29: 000049 | B29: CA3-0027 | C29: Signal 1 | D29: Mono | E29: Present | F29: Present | G29: Present | H29: 38.2 | I29: 5 | J29: -3.3 | K29: 91.9 | L29: 1411.7 | M29: 0.0135 | N29: 232 | O29: No | P29: No – screenshot only | Q29: No – screenshot only | R29: No – screenshot only | S29: No | T29: No | U29: Screenshot 2026-08-02 114640.png | V29: Screenshot 2026-08-02 114709.png | W29: Unreadable/not reliably transcribed: Displayed Radiation Coefficient
A30: 000050 | B30: CA3-0028 | C30: Signal 1 | D30: Mono | E30: Present | F30: Present | G30: Present | H30: 37 | I30: 6.7 | J30: -3.3 | K30: 93.7 | L30: 1384.2 | M30: 0.0134 | N30: 234 | O30: No | P30: No – screenshot only | Q30: No – screenshot only | R30: No – screenshot only | S30: No | T30: No | U30: Screenshot 2026-08-02 114734.png | V30: Screenshot 2026-08-02 114746.png
A31: 000051 | B31: CA3-0029 | C31: Signal 1 | D31: Mono | E31: Present | F31: Present | G31: Present | H31: 41.1 | I31: 7.6 | J31: -4.4 | K31: 96.9 | L31: 1438.2 | M31: 0.0131 | N31: 240.2 | O31: No | P31: No – screenshot only | Q31: No – screenshot only | R31: No – screenshot only | S31: No | T31: No | U31: Screenshot 2026-08-02 114756.png | V31: Screenshot 2026-08-02 114819.png | W31: Unreadable/not reliably transcribed: Displayed Radiation Coefficient
A32: 000052 | B32: CA3-0030 | C32: Signal 1 | D32: Mono | E32: Present | F32: Present | G32: Present | H32: 25.8 | I32: 7.2 | J32: -3.3 | K32: 93.2 | L32: 1285.9 | M32: 0.0144 | N32: 217.8 | O32: No | P32: No – screenshot only | Q32: No – screenshot only | R32: No – screenshot only | S32: No | T32: No | U32: Screenshot 2026-08-02 120029.png | V32: Screenshot 2026-08-02 120041.png
A33: 000053 | B33: CA23-0031 | C33: Signal 1 | D33: Mono | E33: Present | F33: Present | G33: Present | H33: 40.2 | I33: 7.9 | J33: -3.5 | K33: 96.6 | L33: 1213.7 | M33: 0.0147 | N33: 213.3 | O33: No | P33: No – screenshot only | Q33: No – screenshot only | R33: No – screenshot only | S33: No | T33: No | U33: Screenshot 2026-08-02 120113.png | V33: Screenshot 2026-08-02 120219.png
A34: 000054 | B34: CA23-0032 | C34: Signal 1 | D34: Mono | E34: Present | F34: Present | G34: Present | H34: 33.5 | I34: 5.7 | J34: -3.9 | K34: 96.4 | L34: 1397.3 | M34: 0.013 | N34: 240.9 | O34: No | P34: No – screenshot only | Q34: No – screenshot only | R34: No – screenshot only | S34: No | T34: No | U34: Screenshot 2026-08-02 120239.png | V34: Screenshot 2026-08-02 120606.png
A35: 000055 | B35: CA23-0033 | C35: Signal 1 | D35: Mono | E35: Present | F35: Present | G35: Present | H35: 33 | I35: 6.1 | K35: 95.2 | L35: 1318.3 | M35: 0.0146 | N35: 214.7 | O35: No | P35: No – screenshot only | Q35: No – screenshot only | R35: No – screenshot only | S35: No | T35: No | U35: Screenshot 2026-08-02 120654.png | V35: Screenshot 2026-08-02 120728.png | W35: Unreadable/not reliably transcribed: Displayed Radiation Coefficient, Peak Amplitude (dBFS)
A36: 000056 | B36: CA23-0034 | C36: Signal 1 | D36: Mono | E36: Present | F36: Present | G36: Present | H36: 33.9 | I36: 6.1 | J36: -3.3 | K36: 96.1 | L36: 1390.8 | M36: 0.0135 | N36: 233.1 | O36: No | P36: No – screenshot only | Q36: No – screenshot only | R36: No – screenshot only | S36: No | T36: No | U36: Screenshot 2026-08-02 120754.png | V36: Screenshot 2026-08-02 120815.png | W36: Unreadable/not reliably transcribed: Sample Mass (g), Displayed Radiation Coefficient
A37: 000057 | B37: CA23-0035 | C37: Signal 1 | D37: Mono | E37: Present | F37: Present | G37: Present | H37: 33.3 | I37: 7.7 | K37: 93.5 | L37: 1375.9 | M37: 0.0138 | N37: 227.4 | O37: No | P37: No – screenshot only | Q37: No – screenshot only | R37: No – screenshot only | S37: No | T37: No | U37: Screenshot 2026-08-02 120834.png | V37: Screenshot 2026-08-02 120847.png | W37: Unreadable/not reliably transcribed: Displayed Radiation Coefficient, Peak Amplitude (dBFS)
A38: 000058 | B38: CA2-0036 | C38: Signal 1 | D38: Mono | E38: Present | F38: Present | G38: Present | H38: 33.2 | I38: 6.7 | J38: -3.2 | K38: 94.7 | L38: 1260.4 | M38: 0.0154 | N38: 203.5 | O38: No | P38: No – screenshot only | Q38: No – screenshot only | R38: No – screenshot only | S38: No | T38: No | U38: Screenshot 2026-08-02 120914.png | V38: Screenshot 2026-08-02 120944.png
A39: 000059 | B39: CA2-0037 | C39: Signal 1 | D39: Mono | E39: Present | F39: Present | G39: Present | H39: 38.1 | I39: 6.5 | J39: -3.3 | K39: 95.6 | L39: 1429.7 | M39: 0.0131 | N39: 240.4 | O39: No | P39: No – screenshot only | Q39: No – screenshot only | R39: No – screenshot only | S39: No | T39: No | U39: Screenshot 2026-08-02 121158.png | V39: Screenshot 2026-08-02 121225.png | W39: Unreadable/not reliably transcribed: Displayed Radiation Coefficient
A40: 000060 | B40: CA2-0038 | C40: Signal 1 | D40: Mono | E40: Present | F40: Present | G40: Present | H40: 28.8 | I40: 5.8 | J40: -3.2 | K40: 93.9 | L40: 1218.3 | M40: 0.0143 | N40: 220 | O40: No | P40: No – screenshot only | Q40: No – screenshot only | R40: No – screenshot only | S40: No | T40: No | U40: Screenshot 2026-08-02 121233.png | V40: Screenshot 2026-08-02 121243.png
A41: 000061 | B41: CA2-0039 | C41: Signal 1 | D41: Mono | E41: Present | F41: Present | G41: Present | H41: 28.9 | I41: 6.5 | J41: -3.2 | K41: 96.8 | L41: 1259.2 | M41: 0.0151 | N41: 207.7 | O41: No | P41: No – screenshot only | Q41: No – screenshot only | R41: No – screenshot only | S41: No | T41: No | U41: Screenshot 2026-08-02 121250.png | V41: Screenshot 2026-08-02 121304.png
A42: 000062 | B42: CA2-0040 | C42: Signal 1 | D42: Mono | E42: Present | F42: Present | G42: Present | H42: 27.8 | I42: 5.8 | J42: -3.2 | K42: 95.5 | L42: 1252.7 | M42: 0.0157 | N42: 199.9 | O42: No | P42: No – screenshot only | Q42: No – screenshot only | R42: No – screenshot only | S42: No | T42: No | U42: Screenshot 2026-08-02 121311.png | V42: Screenshot 2026-08-02 121324.png
A43: 000063 | B43: CA1-0041 | C43: Signal 1 | D43: Mono | E43: Present | F43: Present | G43: Present | H43: 19.4 | I43: 5.2 | J43: -5.6 | K43: 96.3 | L43: 1230 | M43: 0.0139 | N43: 225.3 | O43: No | P43: No – screenshot only | Q43: No – screenshot only | R43: No – screenshot only | S43: No | T43: No | U43: Screenshot 2026-08-02 121333.png | V43: Screenshot 2026-08-02 121357.png
A44: 000064 | B44: CA1-0042 | C44: Signal 1 | D44: Mono | E44: Present | F44: Present | G44: Present | H44: 20.2 | I44: 4.2 | J44: -3.2 | K44: 96.5 | L44: 1228.8 | M44: 0.0143 | N44: 220.3 | O44: No | P44: No – screenshot only | Q44: No – screenshot only | R44: No – screenshot only | S44: No | T44: No | U44: Screenshot 2026-08-02 121511.png | V44: Screenshot 2026-08-02 121537.png
A45: 000065 | B45: CA1-0043 | C45: Signal 1 | D45: Mono | E45: Present | F45: Present | G45: Present | H45: 22.8 | I45: 5.5 | J45: -3.5 | K45: 90.7 | L45: 1237.7 | M45: 0.014 | N45: 223.9 | O45: No | P45: No – screenshot only | Q45: No – screenshot only | R45: No – screenshot only | S45: No | T45: No | U45: Screenshot 2026-08-02 121551.png | V45: Screenshot 2026-08-02 121626.png | W45: Unreadable/not reliably transcribed: Displayed Radiation Coefficient
...

Sheet Capture Audit
A1: Capture and Transcription Audit
A3: Issue ID | B3: Severity | C3: Affected Material | D3: Finding | E3: Disposition
A4: ARC-001 | B4: Low | C4: Submitted ZIP | D4: The file contains 99 screenshots representing 49 summary/detail specimen pairs plus one duplicate summary image. | E4: 49 unique specimen records compiled; duplicate not counted as a separate specimen.
A5: ARC-002 | B5: Low | C5: Sample 000050 | D5: Two visually duplicate summary-card screenshots are present. | E5: One summary card paired with the detailed analyzer sheet; duplicate preserved only in the source ZIP.
A6: ARC-003 | B6: Medium | C6: Selected fields | D6: Some displayed text is too faint or obscured for reliable transcription. | E6: Fields remain blank and are enumerated in Review Notes; no values were fabricated.
A7: ARC-004 | B7: Medium | C7: All spectral plots | D7: Only rendered plots are available; underlying numerical waveform, FFT-bin, and impulse-response series are absent. | E7: Plots remain embedded as visual evidence; numeric arrays are marked unavailable.

Sheet Batch Statistics
A1: 30-Year Red Cedar Batch Statistics
A3: Metric | B3: Minimum | C3: Average | D3: Maximum | E3: Std. Deviation
A4: Displayed Density (kg/m³) | B4: =MIN('Specimen Master'!H4:H52) | C4: =AVERAGE('Specimen Master'!H4:H52) | D4: =MAX('Specimen Master'!H4:H52) | E4: =STDEV.S('Specimen Master'!H4:H52)
A5: Resonance Frequency (Hz) | B5: =MIN('Specimen Master'!K4:K52) | C5: =AVERAGE('Specimen Master'!K4:K52) | D5: =MAX('Specimen Master'!K4:K52) | E5: =STDEV.S('Specimen Master'!K4:K52)
A6: Q Factor / Sustain | B6: =MIN('Specimen Master'!N4:N52) | C6: =AVERAGE('Specimen Master'!N4:N52) | D6: =MAX('Specimen Master'!N4:N52) | E6: =STDEV.S('Specimen Master'!N4:N52)
A7: Displayed Young's Modulus (GPa) | B7: =MIN('Specimen Master'!P4:P52) | C7: =AVERAGE('Specimen Master'!P4:P52) | D7: =MAX('Specimen Master'!P4:P52) | E7: =STDEV.S('Specimen Master'!P4:P52)
A8: Displayed Radiation Coefficient | B8: =MIN('Specimen Master'!Q4:Q52) | C8: =AVERAGE('Specimen Master'!Q4:Q52) | D8: =MAX('Specimen Master'!Q4:Q52) | E8: =STDEV.S('Specimen Master'!Q4:Q52)
A9: Fitting (%) | B9: =MIN('Specimen Master'!O4:O52) | C9: =AVERAGE('Specimen Master'!O4:O52) | D9: =MAX('Specimen Master'!O4:O52) | E9: =STDEV.S('Specimen Master'!O4:O52)
A12: Specimen count | B12: 49
A13: MB ID range | B13: 000024–000072

Sheet Spectral Sheet Archive
A1: Embedded Summary Cards and Detailed Spectral-Analysis Screens
A2: Rendered plots are preserved visually; no raw waveform, FFT-bin, or impulse-response arrays were supplied.
A4: Sample 000024 | B4: CA-00002 | Summary | H4: CA-00002 | Detailed
A21: Sample 000025 | B21: CA3-0003 | Summary | H21: CA3-0003 | Detailed
A38: Sample 000026 | B38: CA3-0004 | Summary | H38: CA3-0004 | Detailed
A55: Sample 000027 | B55: CA3-0005 | Summary | H55: CA3-0005 | Detailed
A72: Sample 000028 | B72: CA23-0006 | Summary | H72: CA23-0006 | Detailed
A89: Sample 000029 | B89: CA23-0007 | Summary | H89: CA23-0007 | Detailed
A106: Sample 000030 | B106: CA23-0008 | Summary | H106: CA23-0008 | Detailed
A123: Sample 000031 | B123: CA23-0009 | Summary | H123: CA23-0009 | Detailed
A140: Sample 000032 | B140: CA23-0010 | Summary | H140: CA23-0010 | Detailed
A157: Sample 000033 | B157: CA2-0011 | Summary | H157: CA2-0011 | Detailed
A174: Sample 000034 | B174: CA2-0012 | Summary | H174: CA2-0012 | Detailed
A191: Sample 000035 | B191: CA2-0013 | Summary | H191: CA2-0013 | Detailed
... A820: Sample 000072 | B820: CAE-0050 | Summary | H820: CAE-0050 | Detailed
